<!-- <?xml version="1.0" ?> -->
<!-- =================================================================================== -->
<!-- |    This document was autogenerated by xacro from mrm.xacro                      | -->
<!-- |    EDITING THIS FILE BY HAND IS NOT RECOMMENDED                                 | -->
<!-- =================================================================================== -->
<robot name="mrm" xmlns:xacro="http://www.ros.org/wiki/xacro">
  <!-- END - Include -->
  <link name="base_link">
    <inertial>
      <mass value="1024"/>
      <origin rpy="0 0 0" xyz="0 0 0"/>
      <inertia ixx="170.667" ixy="0" ixz="0" iyy="170.667" iyz="0" izz="170.667"/>
    </inertial>
    <collision>
      <origin rpy="0 0 0" xyz="0 0 0"/>
      <geometry>
        <box size="1 1 1"/>
      </geometry>
    </collision>
    <visual>
      <origin rpy="0 0 0" xyz="0 0 0"/>
      <geometry>
        <box size="1 1 1"/>
      </geometry>
    </visual>
  </link>

  <!-- JOINT 1 -->
  <joint name="base_link__link_01" type="revolute">
    <axis xyz="0 0 1"/>
    <limit effort="1000" lower="-3.14" upper="3.14" velocity="0.5"/>
    <origin rpy="0 0 0" xyz="0 0 0.5"/>
    <parent link="base_link"/>
    <child link="link_01"/>
  </joint>
  <transmission name="trans_base_link__link_01">
    <type>transmission_interface/SimpleTransmission</type>
    <joint name="base_link__link_01">
      <hardwareInterface>PositionJointInterface</hardwareInterface>
    </joint>
    <actuator name="motor_base_link__link_01">
      <hardwareInterface>PositionJointInterface</hardwareInterface>
      <mechanicalReduction>1</mechanicalReduction>
    </actuator>
  </transmission>

  <!-- LINK 1 -->
  <link name="link_01">
    <inertial>
      <mass value="157.633"/>
      <origin rpy="0 0 0" xyz="0 0 -0.1"/>
      <inertia ixx="13.235" ixy="0" ixz="0" iyy="13.235" iyz="0" izz="9.655"/>
    </inertial>
    <collision>
      <origin rpy="0 0 0" xyz="0 0 -0.1"/>
      <geometry>
        <mesh filename="package://mrm_description/meshes/Link1-v2.stl" scale="0.001 0.001 0.001"/>
      </geometry>
    </collision>
    <visual>
      <origin rpy="0 0 0" xyz="0 0 -0.1"/>
      <geometry>
        <mesh filename="package://mrm_description/meshes/Link1-v2.stl" scale="0.001 0.001 0.001"/>
      </geometry>
      <material name="light_black"/>
    </visual>
  </link>

  <!-- JOINT 2 -->
  <joint name="link_01__link_02" type="revolute">
    <axis xyz="0 1 0"/>
    <limit effort="1000" lower="0" upper="1.57" velocity="0.5"/>
    <origin rpy="0 0 0" xyz="0 0 0.4"/>
    <parent link="link_01"/>
    <child link="link_02"/>
  </joint>
  <transmission name="trans_link_01__link_02">
    <type>transmission_interface/SimpleTransmission</type>
    <joint name="link_01__link_02">
      <hardwareInterface>PositionJointInterface</hardwareInterface>
    </joint>
    <actuator name="motor_link_01__link_02">
      <hardwareInterface>PositionJointInterface</hardwareInterface>
      <mechanicalReduction>1</mechanicalReduction>
    </actuator>
  </transmission>

  <!-- LINK 2 -->
  <link name="link_02">
    <inertial>
      <mass value="57.906"/>
      <origin rpy="0 0 0" xyz="0 0 0.4"/>
      <inertia ixx="12.679" ixy="0" ixz="0" iyy="12.679" iyz="0" izz="0.651"/>
    </inertial>
    <collision>
      <origin rpy="0 0 0" xyz="0 0 0.4"/>
      <geometry>
        <cylinder length="0.8" radius="0.15"/>
      </geometry>
    </collision>
    <visual>
      <origin rpy="0 0 0" xyz="0 0 0.4"/>
      <geometry>
        <cylinder length="0.8" radius="0.15"/>
      </geometry>
    </visual>
  </link>

  <!-- JOINT 3 -->
  <joint name="link_02__link_03" type="revolute">
    <axis xyz="0 1 0"/>
    <limit effort="1000" lower="0" upper="0.75" velocity="0.5"/>
    <origin rpy="0 0 0" xyz="0 0 0.8"/>
    <parent link="link_02"/>
    <child link="link_03"/>
  </joint>
  <transmission name="trans_link_02__link_03">
    <type>transmission_interface/SimpleTransmission</type>
    <joint name="link_02__link_03">
      <hardwareInterface>PositionJointInterface</hardwareInterface>
    </joint>
    <actuator name="motor_link_02__link_03">
      <hardwareInterface>PositionJointInterface</hardwareInterface>
      <mechanicalReduction>1</mechanicalReduction>
    </actuator>
  </transmission>

  <!-- LINK 3 -->
  <link name="link_03">
    <inertial>
      <mass value="57.906"/>
      <origin rpy="0 0 0" xyz="0 0 0.4"/>
      <inertia ixx="12.679" ixy="0" ixz="0" iyy="12.679" iyz="0" izz="0.651"/>
    </inertial>
    <collision>
      <origin rpy="0 0 0" xyz="0 0 0.4"/>
      <geometry>
        <cylinder length="0.8" radius="0.15"/>
      </geometry>
    </collision>
    <visual>
      <origin rpy="0 0 0" xyz="0 0 0.4"/>
      <geometry>
        <cylinder length="0.8" radius="0.15"/>
      </geometry>
    </visual>
  </link>

  <!-- JOINT 4 -->
  <joint name="link_03__link_05" type="revolute">
    <axis xyz="0 0 1"/>
    <limit effort="1000" lower="0" upper="1.57" velocity="0.5"/>
    <origin rpy="0 0 0" xyz="0 0 0.8"/>
    <parent link="link_03"/>
    <child link="link_05"/>
  </joint>
  <transmission name="trans_link_03__link_05">
    <type>transmission_interface/SimpleTransmission</type>
    <joint name="link_03__link_05">
      <hardwareInterface>PositionJointInterface</hardwareInterface>
    </joint>
    <actuator name="motor_link_03__link_05">
      <hardwareInterface>PositionJointInterface</hardwareInterface>
      <mechanicalReduction>1</mechanicalReduction>
    </actuator>
  </transmission>

  <!-- LINK 5 -->
  <link name="link_05">
    <inertial>
      <mass value="18.056"/>
      <origin rpy="0 0 0" xyz="0 0 0.125"/>
      <inertia ixx="0.479" ixy="0" ixz="0" iyy="0.479" iyz="0" izz="0.204"/>
    </inertial>
    <collision>
      <origin rpy="0 0 0" xyz="0 0 0.125"/>
      <geometry>
        <cylinder length="0.25" radius="0.15"/>
      </geometry>
    </collision>
    <visual>
      <origin rpy="0 0 0" xyz="0 0 0.125"/>
      <geometry>
        <cylinder length="0.25" radius="0.15"/>
      </geometry>
    </visual>
  </link>

  <!-- END - Robot description -->
  <gazebo>
    <plugin name="gazebo_ros_control" filename="libgazebo_ros_control.so">
    <plugin name="joint_state_publisher" filename="libgazebo_ros_joint_state_publisher.so">
    <jointName>base_link__link_01, link_01__link_02, link_02__link_03, link_03__link_05</jointName>
    </plugin>
  </gazebo>
</robot>

