<?xml version="1.0"?>

<!-- BASE LINK -->

<!-- HAVE TO MAKE SURE THAT THERE ARE NO COLLISIONS between the base_link and link_1 -->

<robot name="arm">
	<link name="world"/>
	<link name="base_link">
		
		<inertial>
			<mass value="0.5"/>
			<origin rpy="0 0 0" xyz="0 0 0.025"/>
			<inertia ixx="0.00018" iyy="0.00018" izz="0.00018"
					 ixy="0" ixz="0" iyz="0"/>
		</inertial>

		<visual>
			<geometry>
				<box size="0.1 0.1 0.1"/>
			</geometry>
			<material name="grey">
				<color rgba="0.75 0.75 0.75 1"/>
			</material>
			<origin rpy="0 0 0" xyz="0 0 0.025"/>
		</visual>
		
		<collision>
			<geometry>
				<box size="0.1 0.1 0.1"/>
			</geometry>
			<origin rpy="0 0 0" xyz="0 0 0.025"/>
		</collision>
	
	</link>
	
	<joint name="fixed" type="fixed">
		<parent link="world"/>
		<child link="base_link"/>
	</joint>

<!-- LINK 1 -->

	<link name="link_1">   
	
		<inertial>
			<mass value="1.0"/>
			<origin rpy="0 0 0" xyz="0 0 0.25"/>
			<inertia ixx="0.02146" iyy="0.02146" izz="0.00125"
					 ixy="0" ixz="0" iyz="0"/>
		</inertial>      
		
		<visual>
			<geometry>
				<cylinder length="0.5" radius="0.05"/>
			</geometry>
			<material name="grey">
				<color rgba="0.75 0.75 0.75 1"/>
			</material>
			<origin rpy="0 0 0" xyz="0 0 0.25"/>
		</visual>
		
		<collision>
			<geometry>
				<cylinder length="0.5" radius="0.05"/>
			</geometry>
			<origin rpy="0 0 0" xyz="0 0 0.25"/>
		</collision>
	
	</link>
	
	<joint name="joint_1" type="revolute">
		<!-- THE LINE BELOW IS USED TO DEFINE REVOLUTE JOINT'S PARAMS -->
		<limit upper="1.57" lower="-1.57" velocity="10" effort="10"/>     
		<axis xyz="0 1 0"/>
		<parent link="base_link"/>
		<child link="link_1"/>
		<origin rpy="0 0 0" xyz="0.0 0.0 0.05"/>
	</joint>

<!-- LINK 2 -->

	<link name="link_2">

		<inertial>
			<mass value="1.0"/>
			<origin rpy="0 0 0" xyz="0 0 0.2"/>
			<inertia ixx="0.01396" iyy="0.01396" izz="0.00125"
					 ixy="0" ixz="0" iyz="0"/>
		</inertial>
		
		<visual>
			<geometry>
				<cylinder length="0.4" radius="0.05"/>
			</geometry>
			<material name="grey"/>
			<origin rpy="0 0 0" xyz="0 0 0.2"/>
		</visual>
		
		<collision>
			<geometry>
				<cylinder length="0.4" radius="0.05"/>
			</geometry>
			<origin rpy="0 0 0" xyz="0 0 0.2"/>
		</collision>

	</link>
	
	<joint name="joint_2" type="continuous">
		<axis xyz="0 1 0"/>
		<parent link="link_1"/>
		<child link="link_2"/>
		<origin rpy="0 1.5708 0" xyz="0.0 -0.1 0.45"/>
	</joint>

<!-- END EFFECTOR -->
	
	<link name="link_ee">
		
		<inertial>
			<mass value="1.0"/>
			<inertia ixx="0.00042" iyy="0.00042" izz="0.00042"
					 ixy="0" ixz="0" iyz="0"/>
		</inertial>
		
		<visual>
			<geometry>
				<box size="0.05 0.05 0.05"/>
			</geometry>
			<material name="grey"/>
		</visual>
		
		<collision>
			<geometry>
				<box size="0.05 0.05 0.05"/>
			</geometry>
		</collision>
	
	</link>
	
	<joint name="joint_ee" type="continuous">
		<axis xyz="0 0 1"/>
		<parent link="link_2"/>
		<child link="link_ee"/>
		<origin rpy="0 0 0" xyz="0.0 0.0 0.425"/>
	</joint>

</robot>